<?xml version="1.0"?>
<robot name="matrix_arm_v3">

  <!-- ================= LINKS ================= -->
  <link name="base_link"/>
  <link name="link1"/>
  <link name="link2"/>
  <link name="link3"/>
  <link name="link4"/>
  <link name="link5"/>
  <link name="link6"/>
  <link name="tool_link"/>

  <!-- ================= JOINT 1 ================= -->
  <!-- Base Yaw -->
  <joint name="joint1_base_yaw" type="revolute">
    <parent link="base_link"/>
    <child link="link1"/>
    <origin xyz="0 0 0.05" rpy="0 0 0"/>
    <axis xyz="0 0 1"/>
    <limit lower="-3.14159" upper="3.14159" effort="10" velocity="2"/>
  </joint>

  <!-- ================= JOINT 2 ================= -->
  <!-- Shoulder Pitch -->
  <joint name="joint2_shoulder_pitch" type="revolute">
    <parent link="link1"/>
    <child link="link2"/>
    <origin xyz="0 0 0.058" rpy="0 0 0"/>
    <axis xyz="0 1 0"/>
    <limit lower="-1.5708" upper="1.5708" effort="10" velocity="2"/>
  </joint>

  <!-- ================= JOINT 3 ================= -->
  <!-- Elbow Pitch -->
  <joint name="joint3_elbow_pitch" type="revolute">
    <parent link="link2"/>
    <child link="link3"/>
    <origin xyz="0 0 0.135" rpy="0 0 0"/>
    <axis xyz="0 -1 0"/>
    <limit lower="-1.5708" upper="1.5708" effort="10" velocity="2"/>
  </joint>

  <!-- ================= JOINT 4 ================= -->
  <!-- Wrist Roll 1 -->
  <joint name="joint4_wrist_roll" type="revolute">
    <parent link="link3"/>
    <child link="link4"/>
    <origin xyz="0.03965 0 0.055" rpy="0 0 0"/>
    <axis xyz="1 0 0"/>
    <limit lower="-1.5708" upper="1.5708" effort="5" velocity="3"/>
  </joint>

  <!-- ================= JOINT 5 ================= -->
  <!-- Wrist Pitch -->
  <joint name="joint5_wrist_pitch" type="revolute">
    <parent link="link4"/>
    <child link="link5"/>
    <origin xyz="0.06285 0 0" rpy="0 0 0"/>
    <axis xyz="0 1 0"/>
    <limit lower="-1.5708" upper="1.5708" effort="5" velocity="3"/>
  </joint>

  <!-- ================= JOINT 6 ================= -->
  <!-- Wrist Roll 2 -->
  <joint name="joint6_wrist_roll_2" type="revolute">
    <parent link="link5"/>
    <child link="link6"/>
    <origin xyz="0.055 0 -0.03965" rpy="0 0 0"/>
    <axis xyz="1 0 0"/>
    <limit lower="-1.5708" upper="1.5708" effort="5" velocity="3"/>
  </joint>

  <!-- ================= TOOL (Fixed) ================= -->
  <joint name="tool_mount" type="fixed">
    <parent link="link6"/>
    <child link="tool_link"/>
    <origin xyz="0 0 -0.035" rpy="0 0 0"/>
  </joint>

</robot>
